Watching for file changes with StatReloader
[02/Jul/2025 01:43:31] "GET / HTTP/1.1" 200 10731
[02/Jul/2025 01:43:31] "GET /static/admin/css/fonts.css HTTP/1.1" 404 1817
[02/Jul/2025 01:43:31] "GET / HTTP/1.1" 200 10731
[02/Jul/2025 01:43:31] "GET /static/admin/css/fonts.css HTTP/1.1" 404 1817
[02/Jul/2025 01:43:31] "GET / HTTP/1.1" 200 10731
[02/Jul/2025 01:43:31] "GET /static/admin/css/fonts.css HTTP/1.1" 404 1817
[02/Jul/2025 01:43:32] "GET / HTTP/1.1" 200 10731
[02/Jul/2025 01:43:32] "GET /static/admin/css/fonts.css HTTP/1.1" 404 1817
[02/Jul/2025 01:43:40] "GET / HTTP/1.1" 200 10731
[02/Jul/2025 01:43:40] "GET /static/admin/css/fonts.css HTTP/1.1" 404 1817
[02/Jul/2025 01:43:41] "GET / HTTP/1.1" 200 10731
[02/Jul/2025 01:43:41] "GET /static/admin/css/fonts.css HTTP/1.1" 404 1817
[02/Jul/2025 01:43:41] "GET / HTTP/1.1" 200 10731
[02/Jul/2025 01:43:41] "GET /static/admin/css/fonts.css HTTP/1.1" 404 1817
[02/Jul/2025 01:43:41] "GET / HTTP/1.1" 200 10731
[02/Jul/2025 01:43:41] "GET /static/admin/css/fonts.css HTTP/1.1" 404 1817
[02/Jul/2025 01:43:41] "GET / HTTP/1.1" 200 10731
[02/Jul/2025 01:43:41] "GET /static/admin/css/fonts.css HTTP/1.1" 404 1817
[02/Jul/2025 01:43:41] "GET / HTTP/1.1" 200 10731
[02/Jul/2025 01:43:41] "GET /static/admin/css/fonts.css HTTP/1.1" 404 1817
[02/Jul/2025 01:58:15] "GET / HTTP/1.1" 200 10731
[02/Jul/2025 01:58:15] "GET /static/admin/css/fonts.css HTTP/1.1" 404 1817
[02/Jul/2025 01:58:15] "GET / HTTP/1.1" 200 10731
[02/Jul/2025 01:58:15] "GET /static/admin/css/fonts.css HTTP/1.1" 404 1817
/app/roma/settings.py changed, reloading.
Performing system checks...

System check identified no issues (0 silenced).
July 02, 2025 - 01:43:24
Django version 4.2, using settings 'roma.settings'
Starting development server at http://0.0.0.0:12345/
Quit the server with CONTROL-C.

Watching for file changes with StatReloader
Exception in thread django-main-thread:
Traceback (most recent call last):
  File "/usr/local/lib/python3.9/threading.py", line 980, in _bootstrap_inner
    self.run()
  File "/usr/local/lib/python3.9/threading.py", line 917, in run
    self._target(*self._args, **self._kwargs)
  File "/usr/local/lib/python3.9/site-packages/django/utils/autoreload.py", line 64, in wrapper
    fn(*args, **kwargs)
  File "/usr/local/lib/python3.9/site-packages/django/core/management/commands/runserver.py", line 125, in inner_run
    autoreload.raise_last_exception()
  File "/usr/local/lib/python3.9/site-packages/django/utils/autoreload.py", line 87, in raise_last_exception
    raise _exception[1]
  File "/usr/local/lib/python3.9/site-packages/django/core/management/__init__.py", line 394, in execute
    autoreload.check_errors(django.setup)()
  File "/usr/local/lib/python3.9/site-packages/django/utils/autoreload.py", line 64, in wrapper
    fn(*args, **kwargs)
  File "/usr/local/lib/python3.9/site-packages/django/__init__.py", line 24, in setup
    apps.populate(settings.INSTALLED_APPS)
  File "/usr/local/lib/python3.9/site-packages/django/apps/registry.py", line 91, in populate
    app_config = AppConfig.create(entry)
  File "/usr/local/lib/python3.9/site-packages/django/apps/config.py", line 193, in create
    import_module(entry)
  File "/usr/local/lib/python3.9/importlib/__init__.py", line 127, in import_module
    return _bootstrap._gcd_import(name[level:], package, level)
  File "<frozen importlib._bootstrap>", line 1030, in _gcd_import
  File "<frozen importlib._bootstrap>", line 1007, in _find_and_load
  File "<frozen importlib._bootstrap>", line 984, in _find_and_load_unlocked
ModuleNotFoundError: No module named 'firstroma'
/app/roma/settings.py changed, reloading.
Watching for file changes with StatReloader
/app/roma/settings.py changed, reloading.
Performing system checks...

System check identified no issues (0 silenced).
July 02, 2025 - 02:00:50
Django version 4.2, using settings 'roma.settings'
Starting development server at http://0.0.0.0:12345/
Quit the server with CONTROL-C.

Watching for file changes with StatReloader
Exception in thread django-main-thread:
Traceback (most recent call last):
  File "/usr/local/lib/python3.9/threading.py", line 980, in _bootstrap_inner
    self.run()
  File "/usr/local/lib/python3.9/threading.py", line 917, in run
    self._target(*self._args, **self._kwargs)
  File "/usr/local/lib/python3.9/site-packages/django/utils/autoreload.py", line 64, in wrapper
    fn(*args, **kwargs)
  File "/usr/local/lib/python3.9/site-packages/django/core/management/commands/runserver.py", line 125, in inner_run
    autoreload.raise_last_exception()
  File "/usr/local/lib/python3.9/site-packages/django/utils/autoreload.py", line 87, in raise_last_exception
    raise _exception[1]
  File "/usr/local/lib/python3.9/site-packages/django/core/management/__init__.py", line 394, in execute
    autoreload.check_errors(django.setup)()
  File "/usr/local/lib/python3.9/site-packages/django/utils/autoreload.py", line 64, in wrapper
    fn(*args, **kwargs)
  File "/usr/local/lib/python3.9/site-packages/django/__init__.py", line 24, in setup
    apps.populate(settings.INSTALLED_APPS)
  File "/usr/local/lib/python3.9/site-packages/django/apps/registry.py", line 91, in populate
    app_config = AppConfig.create(entry)
  File "/usr/local/lib/python3.9/site-packages/django/apps/config.py", line 193, in create
    import_module(entry)
  File "/usr/local/lib/python3.9/importlib/__init__.py", line 127, in import_module
    return _bootstrap._gcd_import(name[level:], package, level)
  File "<frozen importlib._bootstrap>", line 1030, in _gcd_import
  File "<frozen importlib._bootstrap>", line 1007, in _find_and_load
  File "<frozen importlib._bootstrap>", line 984, in _find_and_load_unlocked
ModuleNotFoundError: No module named 'init_roma'
/app/roma/settings.py changed, reloading.
Watching for file changes with StatReloader
/app/roma/settings.py changed, reloading.
Performing system checks...

System check identified no issues (0 silenced).
July 02, 2025 - 02:17:36
Django version 4.2, using settings 'roma.settings'
Starting development server at http://0.0.0.0:12345/
Quit the server with CONTROL-C.

Watching for file changes with StatReloader
/app/roma/urls.py changed, reloading.
Performing system checks...

System check identified no issues (0 silenced).
July 02, 2025 - 02:20:19
Django version 4.2, using settings 'roma.settings'
Starting development server at http://0.0.0.0:12345/
Quit the server with CONTROL-C.

Watching for file changes with StatReloader
Exception in thread django-main-thread:
Traceback (most recent call last):
  File "/usr/local/lib/python3.9/threading.py", line 980, in _bootstrap_inner
    self.run()
  File "/usr/local/lib/python3.9/threading.py", line 917, in run
    self._target(*self._args, **self._kwargs)
  File "/usr/local/lib/python3.9/site-packages/django/utils/autoreload.py", line 64, in wrapper
    fn(*args, **kwargs)
  File "/usr/local/lib/python3.9/site-packages/django/core/management/commands/runserver.py", line 133, in inner_run
    self.check(display_num_errors=True)
  File "/usr/local/lib/python3.9/site-packages/django/core/management/base.py", line 485, in check
    all_issues = checks.run_checks(
  File "/usr/local/lib/python3.9/site-packages/django/core/checks/registry.py", line 88, in run_checks
    new_errors = check(app_configs=app_configs, databases=databases)
  File "/usr/local/lib/python3.9/site-packages/django/core/checks/urls.py", line 14, in check_url_config
    return check_resolver(resolver)
  File "/usr/local/lib/python3.9/site-packages/django/core/checks/urls.py", line 24, in check_resolver
    return check_method()
  File "/usr/local/lib/python3.9/site-packages/django/urls/resolvers.py", line 494, in check
    for pattern in self.url_patterns:
  File "/usr/local/lib/python3.9/site-packages/django/utils/functional.py", line 57, in __get__
    res = instance.__dict__[self.name] = self.func(instance)
  File "/usr/local/lib/python3.9/site-packages/django/urls/resolvers.py", line 715, in url_patterns
    patterns = getattr(self.urlconf_module, "urlpatterns", self.urlconf_module)
  File "/usr/local/lib/python3.9/site-packages/django/utils/functional.py", line 57, in __get__
    res = instance.__dict__[self.name] = self.func(instance)
  File "/usr/local/lib/python3.9/site-packages/django/urls/resolvers.py", line 708, in urlconf_module
    return import_module(self.urlconf_name)
  File "/usr/local/lib/python3.9/importlib/__init__.py", line 127, in import_module
    return _bootstrap._gcd_import(name[level:], package, level)
  File "<frozen importlib._bootstrap>", line 1030, in _gcd_import
  File "<frozen importlib._bootstrap>", line 1007, in _find_and_load
  File "<frozen importlib._bootstrap>", line 986, in _find_and_load_unlocked
  File "<frozen importlib._bootstrap>", line 680, in _load_unlocked
  File "<frozen importlib._bootstrap_external>", line 850, in exec_module
  File "<frozen importlib._bootstrap>", line 228, in _call_with_frames_removed
  File "/app/roma/urls.py", line 22, in <module>
    path('init_roma/', include('init_roma.urls')),
NameError: name 'include' is not defined
/app/roma/urls.py changed, reloading.
Performing system checks...

Watching for file changes with StatReloader
Not Found: /
[02/Jul/2025 02:33:30] "GET / HTTP/1.1" 404 2168
Not Found: /
[02/Jul/2025 02:33:30] "GET / HTTP/1.1" 404 2168
Not Found: /
[02/Jul/2025 02:34:15] "GET / HTTP/1.1" 404 2168
Not Found: /
[02/Jul/2025 02:34:15] "GET / HTTP/1.1" 404 2168
Not Found: /
[02/Jul/2025 02:34:15] "GET / HTTP/1.1" 404 2168
/app/roma/urls.py changed, reloading.
Performing system checks...

System check identified no issues (0 silenced).
July 02, 2025 - 02:24:35
Django version 4.2, using settings 'roma.settings'
Starting development server at http://0.0.0.0:12345/
Quit the server with CONTROL-C.

Watching for file changes with StatReloader
Not Found: /
[02/Jul/2025 02:34:36] "GET / HTTP/1.1" 404 2168
Not Found: /
[02/Jul/2025 02:37:34] "GET / HTTP/1.1" 404 2168
/app/roma/urls.py changed, reloading.
Performing system checks...

System check identified no issues (0 silenced).
July 02, 2025 - 02:34:19
Django version 4.2, using settings 'roma.settings'
Starting development server at http://0.0.0.0:12345/
Quit the server with CONTROL-C.

Watching for file changes with StatReloader
Not Found: /
[02/Jul/2025 02:37:50] "GET / HTTP/1.1" 404 2168
Not Found: /
[02/Jul/2025 02:37:50] "GET / HTTP/1.1" 404 2168
Not Found: /
[02/Jul/2025 02:37:50] "GET / HTTP/1.1" 404 2168
Watching for file changes with StatReloader
Not Found: /
[02/Jul/2025 02:39:29] "GET / HTTP/1.1" 404 2168
Not Found: /
[02/Jul/2025 02:39:30] "GET / HTTP/1.1" 404 2168
Not Found: /
[02/Jul/2025 02:39:30] "GET / HTTP/1.1" 404 2168
Not Found: /
[02/Jul/2025 02:39:30] "GET / HTTP/1.1" 404 2168
Not Found: /
[02/Jul/2025 02:39:30] "GET / HTTP/1.1" 404 2168
Not Found: /
[02/Jul/2025 02:39:30] "GET / HTTP/1.1" 404 2168
Not Found: /
[02/Jul/2025 02:39:30] "GET / HTTP/1.1" 404 2168
Not Found: /
[02/Jul/2025 02:39:31] "GET / HTTP/1.1" 404 2168
[02/Jul/2025 02:40:26] "GET /init_roma/ HTTP/1.1" 200 132
[02/Jul/2025 02:47:33] "GET /init_roma/ HTTP/1.1" 200 132
[02/Jul/2025 02:47:34] "GET /init_roma/ HTTP/1.1" 200 132
[02/Jul/2025 02:47:34] "GET /init_roma/ HTTP/1.1" 200 132
[02/Jul/2025 02:47:35] "GET /init_roma/ HTTP/1.1" 200 132
[02/Jul/2025 02:47:35] "GET /init_roma/ HTTP/1.1" 200 132
[02/Jul/2025 02:47:40] "GET /init_roma/about HTTP/1.1" 301 0
[02/Jul/2025 02:47:40] "GET /init_roma/about/ HTTP/1.1" 200 151
[02/Jul/2025 02:50:10] "GET /init_roma/about/ HTTP/1.1" 200 151
/app/roma/urls.py changed, reloading.
Performing system checks...

System check identified no issues (0 silenced).
July 02, 2025 - 02:39:26
Django version 4.2, using settings 'roma.settings'
Starting development server at http://0.0.0.0:12345/
Quit the server with CONTROL-C.

Watching for file changes with StatReloader
Exception in thread django-main-thread:
Traceback (most recent call last):
  File "/usr/local/lib/python3.9/threading.py", line 980, in _bootstrap_inner
    self.run()
  File "/usr/local/lib/python3.9/threading.py", line 917, in run
    self._target(*self._args, **self._kwargs)
  File "/usr/local/lib/python3.9/site-packages/django/utils/autoreload.py", line 64, in wrapper
    fn(*args, **kwargs)
  File "/usr/local/lib/python3.9/site-packages/django/core/management/commands/runserver.py", line 133, in inner_run
    self.check(display_num_errors=True)
  File "/usr/local/lib/python3.9/site-packages/django/core/management/base.py", line 485, in check
    all_issues = checks.run_checks(
  File "/usr/local/lib/python3.9/site-packages/django/core/checks/registry.py", line 88, in run_checks
    new_errors = check(app_configs=app_configs, databases=databases)
  File "/usr/local/lib/python3.9/site-packages/django/core/checks/urls.py", line 14, in check_url_config
    return check_resolver(resolver)
  File "/usr/local/lib/python3.9/site-packages/django/core/checks/urls.py", line 24, in check_resolver
    return check_method()
  File "/usr/local/lib/python3.9/site-packages/django/urls/resolvers.py", line 494, in check
    for pattern in self.url_patterns:
  File "/usr/local/lib/python3.9/site-packages/django/utils/functional.py", line 57, in __get__
    res = instance.__dict__[self.name] = self.func(instance)
  File "/usr/local/lib/python3.9/site-packages/django/urls/resolvers.py", line 715, in url_patterns
    patterns = getattr(self.urlconf_module, "urlpatterns", self.urlconf_module)
  File "/usr/local/lib/python3.9/site-packages/django/utils/functional.py", line 57, in __get__
    res = instance.__dict__[self.name] = self.func(instance)
  File "/usr/local/lib/python3.9/site-packages/django/urls/resolvers.py", line 708, in urlconf_module
    return import_module(self.urlconf_name)
  File "/usr/local/lib/python3.9/importlib/__init__.py", line 127, in import_module
    return _bootstrap._gcd_import(name[level:], package, level)
  File "<frozen importlib._bootstrap>", line 1030, in _gcd_import
  File "<frozen importlib._bootstrap>", line 1007, in _find_and_load
  File "<frozen importlib._bootstrap>", line 986, in _find_and_load_unlocked
  File "<frozen importlib._bootstrap>", line 680, in _load_unlocked
  File "<frozen importlib._bootstrap_external>", line 850, in exec_module
  File "<frozen importlib._bootstrap>", line 228, in _call_with_frames_removed
  File "/app/roma/urls.py", line 23, in <module>
    path('', init.roma.views.home_page, name='root_home-page'),
NameError: name 'init' is not defined
/app/roma/urls.py changed, reloading.
Performing system checks...

Watching for file changes with StatReloader
Exception in thread django-main-thread:
Traceback (most recent call last):
  File "/usr/local/lib/python3.9/threading.py", line 980, in _bootstrap_inner
    self.run()
  File "/usr/local/lib/python3.9/threading.py", line 917, in run
    self._target(*self._args, **self._kwargs)
  File "/usr/local/lib/python3.9/site-packages/django/utils/autoreload.py", line 64, in wrapper
    fn(*args, **kwargs)
  File "/usr/local/lib/python3.9/site-packages/django/core/management/commands/runserver.py", line 133, in inner_run
    self.check(display_num_errors=True)
  File "/usr/local/lib/python3.9/site-packages/django/core/management/base.py", line 485, in check
    all_issues = checks.run_checks(
  File "/usr/local/lib/python3.9/site-packages/django/core/checks/registry.py", line 88, in run_checks
    new_errors = check(app_configs=app_configs, databases=databases)
  File "/usr/local/lib/python3.9/site-packages/django/core/checks/urls.py", line 14, in check_url_config
    return check_resolver(resolver)
  File "/usr/local/lib/python3.9/site-packages/django/core/checks/urls.py", line 24, in check_resolver
    return check_method()
  File "/usr/local/lib/python3.9/site-packages/django/urls/resolvers.py", line 494, in check
    for pattern in self.url_patterns:
  File "/usr/local/lib/python3.9/site-packages/django/utils/functional.py", line 57, in __get__
    res = instance.__dict__[self.name] = self.func(instance)
  File "/usr/local/lib/python3.9/site-packages/django/urls/resolvers.py", line 715, in url_patterns
    patterns = getattr(self.urlconf_module, "urlpatterns", self.urlconf_module)
  File "/usr/local/lib/python3.9/site-packages/django/utils/functional.py", line 57, in __get__
    res = instance.__dict__[self.name] = self.func(instance)
  File "/usr/local/lib/python3.9/site-packages/django/urls/resolvers.py", line 708, in urlconf_module
    return import_module(self.urlconf_name)
  File "/usr/local/lib/python3.9/importlib/__init__.py", line 127, in import_module
    return _bootstrap._gcd_import(name[level:], package, level)
  File "<frozen importlib._bootstrap>", line 1030, in _gcd_import
  File "<frozen importlib._bootstrap>", line 1007, in _find_and_load
  File "<frozen importlib._bootstrap>", line 986, in _find_and_load_unlocked
  File "<frozen importlib._bootstrap>", line 680, in _load_unlocked
  File "<frozen importlib._bootstrap_external>", line 850, in exec_module
  File "<frozen importlib._bootstrap>", line 228, in _call_with_frames_removed
  File "/app/roma/urls.py", line 28, in <module>
    path('', init.roma.views.home_page, name='root_home-page'),
NameError: name 'init' is not defined
/app/roma/urls.py changed, reloading.
Performing system checks...

Watching for file changes with StatReloader
[02/Jul/2025 03:26:50] "GET / HTTP/1.1" 200 132
[02/Jul/2025 03:26:51] "GET / HTTP/1.1" 200 132
[02/Jul/2025 03:26:51] "GET / HTTP/1.1" 200 132
[02/Jul/2025 03:26:51] "GET / HTTP/1.1" 200 132
[02/Jul/2025 03:26:52] "GET / HTTP/1.1" 200 132
[02/Jul/2025 03:26:53] "GET /init_roma/ HTTP/1.1" 200 132
[02/Jul/2025 03:26:54] "GET /init_roma/about/ HTTP/1.1" 200 151
[02/Jul/2025 03:26:56] "GET / HTTP/1.1" 200 132
[02/Jul/2025 03:26:56] "GET / HTTP/1.1" 200 132
[02/Jul/2025 03:26:56] "GET / HTTP/1.1" 200 132
[02/Jul/2025 03:26:56] "GET / HTTP/1.1" 200 132
[02/Jul/2025 03:26:56] "GET / HTTP/1.1" 200 132
[02/Jul/2025 03:26:57] "GET / HTTP/1.1" 200 132
[02/Jul/2025 03:26:57] "GET / HTTP/1.1" 200 132
[02/Jul/2025 03:26:57] "GET / HTTP/1.1" 200 132
[02/Jul/2025 03:26:57] "GET / HTTP/1.1" 200 132
[02/Jul/2025 03:26:57] "GET / HTTP/1.1" 200 132
